<?xml version="1.0" ?>
<!-- Generated using onshape-to-robot -->
<!-- Onshape https://cad.onshape.com/documents/194cfea5024b4d52f52858ab/w/427e8563680111b57e8c1ddc/e/754bbf98c843a5e8f497d059 -->
<mujoco model="humanoid">
  <compiler angle="radian" meshdir="assets" autolimits="true"/>
  <default>
    <default class="humanoid">
      <joint frictionloss="0.1" armature="0.005"/>
      <position kp="50" dampratio="1"/>
      <default class="visual">
        <geom type="mesh" contype="0" conaffinity="0" group="2"/>
      </default>
      <default class="collision">
        <geom group="3"/>
      </default>
    </default>
  </default>
  <worldbody>
    <!-- Link body -->
    <body name="body" pos="0 0 0" quat="1 0 0 0" childclass="humanoid">
      <freejoint name="body_freejoint"/>
      <inertial pos="-0.018942 0.001457 0.251179" mass="3.84565" fullinertia="0.0725231 0.0594733 0.020516 -7.84446e-05 -0.00258411 8.83924e-05"/>
      <!-- Part body_parts -->
      <geom type="mesh" class="visual" pos="-0.018942 0.001457 0.251179" quat="1 0 0 0" mesh="body_visual" material="body_visual_material"/>
      <geom type="mesh" class="collision" pos="-0.018942 0.001457 0.251179" quat="1 0 0 0" mesh="body_collision" material="body_collision_material"/>
      <!-- Link body_lower -->
      <body name="body_lower" pos="-0.01518 0 -0.012" quat="0 0 0 -1">
        <!-- Joint from body to body_lower -->
        <joint axis="0 0 1" name="body_yaw" type="hinge" range="-0.523599 0.523599"/>
        <inertial pos="0 0 -0.100256" mass="4.17833" fullinertia="0.0141195 0.0135919 0.00778336 -2.25187e-09 -1.12383e-05 -9.16379e-09"/>
        <!-- Part body_lower_parts -->
        <geom type="mesh" class="visual" pos="0 0 -0.100256" quat="0 0 0 1" mesh="body_lower_visual" material="body_lower_visual_material"/>
        <geom type="mesh" class="collision" pos="0 0 -0.100256" quat="0 0 0 1" mesh="body_lower_collision" material="body_lower_collision_material"/>
        <!-- Link hip_abd_mount_left -->
        <body name="hip_abd_mount_left" pos="0 -0.053 -0.1225" quat="0 0 -0.707107 -0.707107">
          <!-- Joint from body_lower to hip_abd_mount_left -->
          <joint axis="0 0 1" name="left_hip_flex" type="hinge" range="-0.174533 2.443461"/>
          <inertial pos="0 0 -0.056763" mass="1.01306" fullinertia="0.00136129 0.000959765 0.000933639 -1.7053e-11 -5.14102e-07 2.21242e-10"/>
          <!-- Part hip_abd_mount_left_parts -->
          <geom type="mesh" class="visual" pos="0 0 -0.056763" quat="0.707107 -0.707107 0 0" mesh="hip_abd_mount_left_visual" material="hip_abd_mount_left_visual_material"/>
          <geom type="mesh" class="collision" pos="0 0 -0.056763" quat="0.707107 -0.707107 0 0" mesh="hip_abd_mount_left_collision" material="hip_abd_mount_left_collision_material"/>
          <!-- Link leg_upper_upper_left -->
          <body name="leg_upper_upper_left" pos="0.0282 0 -0.0595" quat="0.707107 0 -0.707107 0">
            <!-- Joint from hip_abd_mount_left to leg_upper_upper_left -->
            <joint axis="0 0 1" name="left_hip_ab" type="hinge" range="-0.523599 0.174533"/>
            <inertial pos="0.01404 -0.111217 0.028175" mass="1.123" fullinertia="0.00190274 0.00165145 0.00176373 9.30994e-05 -4.13147e-06 2.54422e-05"/>
            <!-- Part leg_upper_upper_left_parts -->
            <geom type="mesh" class="visual" pos="0.01404 -0.111217 0.028175" quat="0.5 -0.5 0.5 0.5" mesh="leg_upper_upper_left_visual" material="leg_upper_upper_left_visual_material"/>
            <geom type="mesh" class="collision" pos="0.01404 -0.111217 0.028175" quat="0.5 -0.5 0.5 0.5" mesh="leg_upper_upper_left_collision" material="leg_upper_upper_left_collision_material"/>
            <!-- Link knee_motor_mount -->
            <body name="knee_motor_mount" pos="0.015 -0.1454 0.0283" quat="0.5 -0.5 -0.5 -0.5">
              <!-- Joint from leg_upper_upper_left to knee_motor_mount -->
              <joint axis="0 0 1" name="left_hip_rot" type="hinge" range="-0.785398 0.785398"/>
              <inertial pos="-0.019378 0 -0.160764" mass="1.041" fullinertia="0.00214858 0.00253248 0.000938413 8.56138e-07 -8.14148e-05 -6.85493e-05"/>
              <!-- Part knee_motor_mount_parts -->
              <geom type="mesh" class="visual" pos="-0.019378 0 -0.160764" quat="0 0 0 1" mesh="knee_motor_mount_visual" material="knee_motor_mount_visual_material"/>
              <geom type="mesh" class="collision" pos="-0.019378 0 -0.160764" quat="0 0 0 1" mesh="knee_motor_mount_collision" material="knee_motor_mount_collision_material"/>
              <!-- Link leg_lower_left -->
              <body name="leg_lower_left" pos="-0.019665 -0.0275 -0.1711" quat="0.5 -0.5 0.5 0.5">
                <!-- Joint from knee_motor_mount to leg_lower_left -->
                <joint axis="0 0 1" name="left_knee" type="hinge" range="-1.658063 0.174533"/>
                <inertial pos="0.163698 -0.017632 0.027147" mass="1.52106" fullinertia="0.00100369 0.014844 0.0148515 0.000128089 -0.000834107 5.60807e-05"/>
                <!-- Part leg_lower_left_parts -->
                <geom type="mesh" class="visual" pos="0.163698 -0.017632 0.027147" quat="0.5 -0.5 -0.5 0.5" mesh="leg_lower_left_visual" material="leg_lower_left_visual_material"/>
                <geom type="mesh" class="collision" pos="0.163698 -0.017632 0.027147" quat="0.5 -0.5 -0.5 0.5" mesh="leg_lower_left_collision" material="leg_lower_left_collision_material"/>
                <!-- Link u_join_box_left -->
                <body name="u_join_box_left" pos="0.405551 -0.021 0.0233" quat="0 0.707107 0.707107 0">
                  <!-- Joint from leg_lower_left to u_join_box_left -->
                  <joint axis="0 0 1" name="left_foot_pitch" type="hinge" range="-1.047217 1.047179"/>
                  <inertial pos="0 0 -0.0085" mass="0.0105657" fullinertia="4.06576e-07 3.53173e-07 4.06576e-07 2.16416e-13 1.51588e-17 -7.98128e-13"/>
                  <!-- Part u_join_box_left_parts -->
                  <geom type="mesh" class="visual" pos="0 0 -0.0085" quat="0.707107 0.707107 0 0" mesh="u_join_box_left_visual" material="u_join_box_left_visual_material"/>
                  <geom type="mesh" class="collision" pos="0 0 -0.0085" quat="0.707107 0.707107 0 0" mesh="u_join_box_left_collision" material="u_join_box_left_collision_material"/>
                  <!-- Link left_foot -->
                  <body name="left_foot" pos="0.0085 0 -0.0085" quat="0 0.707107 0 -0.707107">
                    <!-- Joint from u_join_box_left to left_foot -->
                    <joint axis="0 0 1" name="left_foot_roll" type="hinge" range="-1.047198 1.047198"/>
                    <inertial pos="0 -0.031111 -0.005042" mass="0.265073" fullinertia="0.000692941 0.000772156 0.000191201 4.56429e-10 2.74043e-09 -3.66785e-05"/>
                    <!-- Part left_foot_parts -->
                    <geom type="mesh" class="visual" pos="0 -0.031111 -0.005042" quat="0.500005 -0.499995 0.499995 0.500005" mesh="left_foot_visual" material="left_foot_visual_material"/>
                    <geom type="mesh" class="collision" pos="0 -0.031111 -0.005042" quat="0.500005 -0.499995 0.499995 0.500005" mesh="left_foot_collision" material="left_foot_collision_material"/>
                    <!-- Frame closing_left_ankle_left_linkage_2 -->
                    <site group="3" name="closing_left_ankle_left_linkage_2" pos="-0.02725 0 0.0485" quat="0.707107 0 0.707107 0"/>
                    <!-- Frame closing_left_ankle_right_linkage_2 -->
                    <site group="3" name="closing_left_ankle_right_linkage_2" pos="0.02725 0 0.0485" quat="0 -0.707107 0 0.707107"/>
                  </body>
                </body>
                <!-- Link lever -->
                <body name="lever" pos="0.10955 -0.021 0.00905" quat="0.707107 0 0 -0.707107">
                  <!-- Joint from leg_lower_left to lever -->
                  <joint axis="0 0 1" name="left_ankle" type="hinge" range="-0.785398 0.785398"/>
                  <inertial pos="0.007421 0 -0.008202" mass="0.04016" fullinertia="3.33236e-06 1.05394e-05 1.15772e-05 1.20845e-13 2.37954e-07 -1.96953e-13"/>
                  <!-- Part lever_parts -->
                  <geom type="mesh" class="visual" pos="0.007421 0 -0.008202" quat="0 0 0.707107 -0.707107" mesh="lever_visual" material="lever_visual_material"/>
                  <geom type="mesh" class="collision" pos="0.007421 0 -0.008202" quat="0 0 0.707107 -0.707107" mesh="lever_collision" material="lever_collision_material"/>
                  <!-- Link linkage_long -->
                  <body name="linkage_long" pos="0.04 0 -0.0045" quat="0 0.074899 0 -0.997191">
                    <!-- Joint from lever to linkage_long -->
                    <joint axis="0 0 1" name="left_ankle_lever" type="ball" range="0 1.570796"/>
                    <inertial pos="0 -0.148 -0.0045" mass="0.088" fullinertia="0.000691208 7.3124e-07 0.000690751 -7.82826e-30 -3.08455e-20 -6.97262e-29"/>
                    <!-- Part linkage_long_parts -->
                    <geom type="mesh" class="visual" pos="0 -0.148 -0.0045" quat="0.705121 -0.705121 -0.052961 -0.052961" mesh="linkage_long_visual" material="linkage_long_visual_material"/>
                    <geom type="mesh" class="collision" pos="0 -0.148 -0.0045" quat="0.705121 -0.705121 -0.052961 -0.052961" mesh="linkage_long_collision" material="linkage_long_collision_material"/>
                    <!-- Frame closing_left_ankle_left_linkage_1 -->
                    <site group="3" name="closing_left_ankle_left_linkage_1" pos="0 -0.296 0" quat="1 0 0 0"/>
                  </body>
                </body>
                <!-- Link lever_2 -->
                <body name="lever_2" pos="0.18955 -0.021 0.05455" quat="0 0.707107 0.707107 0">
                  <!-- Joint from leg_lower_left to lever_2 -->
                  <joint axis="0 0 1" name="left_ankle_lower" type="hinge" range="-0.785398 0.785398"/>
                  <inertial pos="-0.007421 0 -0.008202" mass="0.04016" fullinertia="3.33236e-06 1.05394e-05 1.15772e-05 1.51001e-13 -2.37954e-07 1.97948e-13"/>
                  <!-- Part lever_2_parts -->
                  <geom type="mesh" class="visual" pos="-0.007421 0 -0.008202" quat="0.707107 0.707107 0 0" mesh="lever_2_visual" material="lever_2_visual_material"/>
                  <geom type="mesh" class="collision" pos="-0.007421 0 -0.008202" quat="0.707107 0.707107 0 0" mesh="lever_2_collision" material="lever_2_collision_material"/>
                  <!-- Link linkage_short -->
                  <body name="linkage_short" pos="-0.04 0 -0.0045" quat="0.998211 0 -0.059784 0">
                    <!-- Joint from lever_2 to linkage_short -->
                    <joint axis="0 0 1" name="left_ankle_lever_lower" type="ball" range="0 1.570796"/>
                    <inertial pos="0 0.108 -0.0045" mass="0.078" fullinertia="0.000334788 6.54358e-07 0.00033439 -3.38878e-30 3.16084e-21 -1.66447e-29"/>
                    <!-- Part linkage_short_parts -->
                    <geom type="mesh" class="visual" pos="0 0.108 -0.0045" quat="0.705842 0.705842 0.042274 -0.042274" mesh="linkage_short_visual" material="linkage_short_visual_material"/>
                    <geom type="mesh" class="collision" pos="0 0.108 -0.0045" quat="0.705842 0.705842 0.042274 -0.042274" mesh="linkage_short_collision" material="linkage_short_collision_material"/>
                    <!-- Frame closing_left_ankle_right_linkage_1 -->
                    <site group="3" name="closing_left_ankle_right_linkage_1" pos="0 0.216 0" quat="1 0 0 0"/>
                  </body>
                </body>
              </body>
            </body>
          </body>
        </body>
        <!-- Link hip_abd_mount_right -->
        <body name="hip_abd_mount_right" pos="0 0.053 -0.1225" quat="0 0 0.707107 -0.707107">
          <!-- Joint from body_lower to hip_abd_mount_right -->
          <joint axis="0 0 1" name="right_hip_flex" type="hinge" range="-2.443461 0.174533"/>
          <inertial pos="0 0 -0.056763" mass="1.01306" fullinertia="0.00136129 0.000959765 0.000933639 -5.17911e-12 -5.14126e-07 -1.73963e-11"/>
          <!-- Part hip_abd_mount_right_parts -->
          <geom type="mesh" class="visual" pos="0 0 -0.056763" quat="0.707107 0.707107 0 0" mesh="hip_abd_mount_right_visual" material="hip_abd_mount_right_visual_material"/>
          <geom type="mesh" class="collision" pos="0 0 -0.056763" quat="0.707107 0.707107 0 0" mesh="hip_abd_mount_right_collision" material="hip_abd_mount_right_collision_material"/>
          <!-- Link leg_upper_upper_right -->
          <body name="leg_upper_upper_right" pos="0.0282 0 -0.0595" quat="0 -0.707107 0 0.707107">
            <!-- Joint from hip_abd_mount_right to leg_upper_upper_right -->
            <joint axis="0 0 1" name="right_hip_ab" type="hinge" range="-0.174533 0.349066"/>
            <inertial pos="-0.013273 -0.105288 0.027906" mass="1.36027" fullinertia="0.00309815 0.00220595 0.00279118 -0.000188917 9.76418e-06 6.12101e-05"/>
            <!-- Part leg_upper_upper_right_parts -->
            <geom type="mesh" class="visual" pos="-0.013273 -0.105288 0.027906" quat="0.5 -0.5 0.5 0.5" mesh="leg_upper_upper_right_visual" material="leg_upper_upper_right_visual_material"/>
            <geom type="mesh" class="collision" pos="-0.013273 -0.105288 0.027906" quat="0.5 -0.5 0.5 0.5" mesh="leg_upper_upper_right_collision" material="leg_upper_upper_right_collision_material"/>
            <!-- Link knee_motor_mount_right -->
            <body name="knee_motor_mount_right" pos="-0.015 -0.1454 0.0283" quat="0.5 -0.5 -0.5 -0.5">
              <!-- Joint from leg_upper_upper_right to knee_motor_mount_right -->
              <joint axis="0 0 1" name="right_hip_rot" type="hinge" range="-0.785398 0.785399"/>
              <inertial pos="-0.019378 0 -0.160764" mass="1.041" fullinertia="0.00215111 0.00253248 0.000935882 -8.56093e-07 -8.14145e-05 6.85484e-05"/>
              <!-- Part knee_motor_mount_right_parts -->
              <geom type="mesh" class="visual" pos="-0.019378 0 -0.160764" quat="0 0 0 1" mesh="knee_motor_mount_right_visual" material="knee_motor_mount_right_visual_material"/>
              <geom type="mesh" class="collision" pos="-0.019378 0 -0.160764" quat="0 0 0 1" mesh="knee_motor_mount_right_collision" material="knee_motor_mount_right_collision_material"/>
              <!-- Link leg_lower_right -->
              <body name="leg_lower_right" pos="-0.019665 0.0275 -0.1711" quat="0.707107 0.707107 0 0">
                <!-- Joint from knee_motor_mount_right to leg_lower_right -->
                <joint axis="0 0 1" name="right_knee" type="hinge" range="-0.174533 1.658062"/>
                <inertial pos="0.017629 -0.163639 0.027159" mass="1.52306" fullinertia="0.0148587 0.00100547 0.0148659 0.000127202 -5.5986e-05 0.000832299"/>
                <!-- Part leg_lower_right_parts -->
                <geom type="mesh" class="visual" pos="0.017629 -0.163639 0.027159" quat="0 0 -0.707107 -0.707107" mesh="leg_lower_right_visual" material="leg_lower_right_visual_material"/>
                <geom type="mesh" class="collision" pos="0.017629 -0.163639 0.027159" quat="0 0 -0.707107 -0.707107" mesh="leg_lower_right_collision" material="leg_lower_right_collision_material"/>
                <!-- Link u_join_box_right -->
                <body name="u_join_box_right" pos="0.021 -0.405551 0.0403" quat="0 0 0 -1">
                  <!-- Joint from leg_lower_right to u_join_box_right -->
                  <joint axis="0 0 1" name="right_foot_pitch" type="hinge" range="-1.047217 1.047179"/>
                  <inertial pos="0 0 -0.0085" mass="0.0105657" fullinertia="4.06576e-07 3.53173e-07 4.06576e-07 1.81278e-12 -1.5164e-17 7.98128e-13"/>
                  <!-- Part u_join_box_right_parts -->
                  <geom type="mesh" class="visual" pos="0 0 -0.0085" quat="0.707107 0.707107 0 0" mesh="u_join_box_right_visual" material="u_join_box_right_visual_material"/>
                  <geom type="mesh" class="collision" pos="0 0 -0.0085" quat="0.707107 0.707107 0 0" mesh="u_join_box_right_collision" material="u_join_box_right_collision_material"/>
                  <!-- Link right_foot -->
                  <body name="right_foot" pos="0.0085 0 -0.0085" quat="0 0.707107 0 -0.707107">
                    <!-- Joint from u_join_box_right to right_foot -->
                    <joint axis="0 0 1" name="right_foot_roll" type="hinge" range="-1.047198 1.047198"/>
                    <inertial pos="0 -0.031111 -0.005042" mass="0.265073" fullinertia="0.000692948 0.000772164 0.000191201 3.80234e-10 3.65325e-09 -3.66766e-05"/>
                    <!-- Part right_foot_parts -->
                    <geom type="mesh" class="visual" pos="0 -0.031111 -0.005042" quat="0.500005 -0.499995 0.499995 0.500005" mesh="right_foot_visual" material="right_foot_visual_material"/>
                    <geom type="mesh" class="collision" pos="0 -0.031111 -0.005042" quat="0.500005 -0.499995 0.499995 0.500005" mesh="right_foot_collision" material="right_foot_collision_material"/>
                    <!-- Frame closing_right_ankle_right_linkage_1 -->
                    <site group="3" name="closing_right_ankle_right_linkage_1" pos="0.02725 0 0.0485" quat="0.707107 0 0.707107 0"/>
                    <!-- Frame closing_right_ankle_left_linkage_2 -->
                    <site group="3" name="closing_right_ankle_left_linkage_2" pos="-0.02725 0 0.0485" quat="0 -0.707107 0 -0.707107"/>
                  </body>
                </body>
                <!-- Link lever_3 -->
                <body name="lever_3" pos="0.021 -0.10955 0.00905" quat="0.984808 0 0 0.173648">
                  <!-- Joint from leg_lower_right to lever_3 -->
                  <joint axis="0 0 1" name="right_ankle" type="hinge" range="-0.436332 1.134464"/>
                  <inertial pos="0.006974 -0.002538 -0.008202" mass="0.04016" fullinertia="4.17543e-06 9.69635e-06 1.15772e-05 2.3163e-06 2.23603e-07 -8.13851e-08"/>
                  <!-- Part lever_3_parts -->
                  <geom type="mesh" class="visual" pos="0.006974 -0.002538 -0.008202" quat="0.122788 0.122788 0.696364 0.696364" mesh="lever_3_visual" material="lever_3_visual_material"/>
                  <geom type="mesh" class="collision" pos="0.006974 -0.002538 -0.008202" quat="0.122788 0.122788 0.696364 0.696364" mesh="lever_3_collision" material="lever_3_collision_material"/>
                  <!-- Link linkage_long_right -->
                  <body name="linkage_long_right" pos="0.037588 -0.013681 -0.0135" quat="0 -0.173648 -0.984808 0">
                    <!-- Joint from lever_3 to linkage_long_right -->
                    <joint axis="0 0 1" name="right_ankle_lever" type="ball" range="0 1.570796"/>
                    <inertial pos="0 -0.148 -0.0045" mass="0.078" fullinertia="0.000612661 6.48307e-07 0.000612257 -3.15119e-07 6.85351e-09 -2.67008e-09"/>
                    <!-- Part linkage_long_right_parts -->
                    <geom type="mesh" class="visual" pos="0 -0.148 -0.0045" quat="0.707107 -0.707107 0 0" mesh="linkage_long_right_visual" material="linkage_long_right_visual_material"/>
                    <geom type="mesh" class="collision" pos="0 -0.148 -0.0045" quat="0.707107 -0.707107 0 0" mesh="linkage_long_right_collision" material="linkage_long_right_collision_material"/>
                    <!-- Frame closing_right_ankle_right_linkage_2 -->
                    <site group="3" name="closing_right_ankle_right_linkage_2" pos="0 -0.296 -0.009" quat="0.999964 0 -0.008467 0"/>
                  </body>
                </body>
                <!-- Link lever_4 -->
                <body name="lever_4" pos="0.021 -0.18955 0.05455" quat="0 -0.984808 -0.173648 0">
                  <!-- Joint from leg_lower_right to lever_4 -->
                  <joint axis="0 0 1" name="right_ankle_lower" type="hinge" range="-1.134464 0.436332"/>
                  <inertial pos="0.006974 0.002538 -0.008202" mass="0.04016" fullinertia="4.17543e-06 9.69635e-06 1.15772e-05 -2.3163e-06 2.23603e-07 8.13848e-08"/>
                  <!-- Part lever_4_parts -->
                  <geom type="mesh" class="visual" pos="0.006974 0.002538 -0.008202" quat="0.122788 -0.122788 0.696364 -0.696364" mesh="lever_4_visual" material="lever_4_visual_material"/>
                  <geom type="mesh" class="collision" pos="0.006974 0.002538 -0.008202" quat="0.122788 -0.122788 0.696364 -0.696364" mesh="lever_4_collision" material="lever_4_collision_material"/>
                  <!-- Link linkage_short_right -->
                  <body name="linkage_short_right" pos="0.037588 0.013681 -0.0045" quat="0.173648 0 0 -0.984808">
                    <!-- Joint from lever_4 to linkage_short_right -->
                    <joint axis="0 0 1" name="right_ankle_lever_lower" type="ball" range="0 1.570796"/>
                    <inertial pos="0 -0.108 -0.004497" mass="0.078" fullinertia="0.000334788 6.54358e-07 0.00033439 1.11906e-14 -1.52631e-08 3.97631e-19"/>
                    <!-- Part linkage_short_right_parts -->
                    <geom type="mesh" class="visual" pos="0 -0.108 -0.004497" quat="0.707107 -0.707107 0 0" mesh="linkage_short_right_visual" material="linkage_short_right_visual_material"/>
                    <geom type="mesh" class="collision" pos="0 -0.108 -0.004497" quat="0.707107 -0.707107 0 0" mesh="linkage_short_right_collision" material="linkage_short_right_collision_material"/>
                    <!-- Frame closing_right_ankle_left_linkage_1 -->
                    <site group="3" name="closing_right_ankle_left_linkage_1" pos="0 -0.216 0" quat="0 -0.019162 0 -0.999816"/>
                  </body>
                </body>
              </body>
            </body>
          </body>
        </body>
      </body>
      <!-- Link neck -->
      <body name="neck" pos="-0.018634 0 0.409" quat="0 -1 0 0">
        <!-- Joint from body to neck -->
        <joint axis="0 0 1" name="head_yaw" type="hinge" range="-1.396263 1.396263"/>
        <inertial pos="0 0 -0.093858" mass="0.635067" fullinertia="0.000923446 0.00102116 0.000375147 -8.90935e-07 -1.4635e-05 2.34101e-07"/>
        <!-- Part neck_parts -->
        <geom type="mesh" class="visual" pos="0 0 -0.093858" quat="0 1 0 0" mesh="neck_visual" material="neck_visual_material"/>
        <geom type="mesh" class="collision" pos="0 0 -0.093858" quat="0 1 0 0" mesh="neck_collision" material="neck_collision_material"/>
        <!-- Link head -->
        <body name="head" pos="0 0.0226 -0.10905" quat="0.030844 0.030844 -0.706434 0.706434">
          <!-- Joint from neck to head -->
          <joint axis="0 0 1" name="head_pitch" type="hinge" range="-0.436332 0.610865"/>
          <inertial pos="-0.019825 0.065065 0.016491" mass="0.407762" fullinertia="0.0028331 0.00158323 0.00197824 -4.25031e-05 3.71607e-05 -0.000127121"/>
          <!-- Part head_parts -->
          <geom type="mesh" class="visual" pos="-0.019825 0.065065 0.016491" quat="0.030844 0.030844 -0.706434 -0.706434" mesh="head_visual" material="head_visual_material"/>
          <geom type="mesh" class="collision" pos="-0.019825 0.065065 0.016491" quat="0.030844 0.030844 -0.706434 -0.706434" mesh="head_collision" material="head_collision_material"/>
        </body>
      </body>
      <!-- Link right_arm_shoulder_mount -->
      <body name="right_arm_shoulder_mount" pos="-0.01518 -0.102068 0.316865" quat="0.642788 -0.766044 0 0">
        <!-- Joint from body to right_arm_shoulder_mount -->
        <joint axis="0 0 1" name="right_arm_flex" type="hinge" range="-3.141593 0.872665"/>
        <inertial pos="0.001316 0 -0.062997" mass="0.460743" fullinertia="0.000394338 0.00030453 0.000233834 2.00509e-06 -4.61876e-06 4.06605e-06"/>
        <!-- Part right_arm_shoulder_mount_parts -->
        <geom type="mesh" class="visual" pos="0.001316 0 -0.062997" quat="0.642788 0.766044 0 0" mesh="right_arm_shoulder_mount_visual" material="right_arm_shoulder_mount_visual_material"/>
        <geom type="mesh" class="collision" pos="0.001316 0 -0.062997" quat="0.642788 0.766044 0 0" mesh="right_arm_shoulder_mount_collision" material="right_arm_shoulder_mount_collision_material"/>
        <!-- Link right_arm_top -->
        <body name="right_arm_top" pos="0.0242 0 -0.0675" quat="0.707107 0 -0.707107 0">
          <!-- Joint from right_arm_shoulder_mount to right_arm_top -->
          <joint axis="0 0 1" name="right_arm_ab" type="hinge" range="-0.523599 2.617994"/>
          <inertial pos="0 0.089956 0.025957" mass="0.5068" fullinertia="0.000598242 0.000396287 0.000549921 1.2354e-07 2.30525e-08 2.34852e-05"/>
          <!-- Part right_arm_top_parts -->
          <geom type="mesh" class="visual" pos="0 0.089956 0.025957" quat="0.454519 0.541675 0.454519 -0.541675" mesh="right_arm_top_visual" material="right_arm_top_visual_material"/>
          <geom type="mesh" class="collision" pos="0 0.089956 0.025957" quat="0.454519 0.541675 0.454519 -0.541675" mesh="right_arm_top_collision" material="right_arm_top_collision_material"/>
          <!-- Link right_arm_elbow -->
          <body name="right_arm_elbow" pos="0 0.1212 0.02545" quat="0.707107 0.707107 0 0">
            <!-- Joint from right_arm_top to right_arm_elbow -->
            <joint axis="0 0 1" name="right_arm_rot" type="hinge" range="-0.785398 0.785398"/>
            <inertial pos="-0.001237 0.002371 -0.109567" mass="0.5242" fullinertia="0.000879285 0.000744675 0.00029075 -1.07228e-06 -8.77294e-06 -8.75276e-05"/>
            <!-- Part right_arm_elbow_parts -->
            <geom type="mesh" class="visual" pos="-0.001237 0.002371 -0.109567" quat="0.704416 0.061628 -0.061628 -0.704416" mesh="right_arm_elbow_visual" material="right_arm_elbow_visual_material"/>
            <geom type="mesh" class="collision" pos="-0.001237 0.002371 -0.109567" quat="0.704416 0.061628 -0.061628 -0.704416" mesh="right_arm_elbow_collision" material="right_arm_elbow_collision_material"/>
            <!-- Link right_arm_lower_back -->
            <body name="right_arm_lower_back" pos="-0.02555 0 -0.121" quat="0.5 0.5 0.5 0.5">
              <!-- Joint from right_arm_elbow to right_arm_lower_back -->
              <joint axis="0 0 1" name="right_arm_elbow" type="hinge" range="-2.094395 0"/>
              <inertial pos="0.005553 -0.084365 0.028884" mass="0.0923" fullinertia="0.00031165 4.32479e-05 0.000299733 1.94132e-05 1.728e-06 -2.62219e-05"/>
              <!-- Part right_arm_lower_back_parts -->
              <geom type="mesh" class="visual" pos="0.005553 -0.084365 0.028884" quat="0 0 -0.766044 -0.642788" mesh="right_arm_lower_back_visual" material="right_arm_lower_back_visual_material"/>
              <geom type="mesh" class="collision" pos="0.005553 -0.084365 0.028884" quat="0 0 -0.766044 -0.642788" mesh="right_arm_lower_back_collision" material="right_arm_lower_back_collision_material"/>
            </body>
          </body>
        </body>
      </body>
      <!-- Link left_arm_shoulder_mount -->
      <body name="left_arm_shoulder_mount" pos="-0.015183 0.102467 0.316905" quat="0.642788 0.766044 0 0">
        <!-- Joint from body to left_arm_shoulder_mount -->
        <joint axis="0 0 1" name="left_arm_flex" type="hinge" range="-0.523599 3.141593"/>
        <inertial pos="0.001316 0 -0.062997" mass="0.460743" fullinertia="0.000394338 0.00030453 0.000233834 -2.00505e-06 -4.6188e-06 -4.06605e-06"/>
        <!-- Part left_arm_shoulder_mount_parts -->
        <geom type="mesh" class="visual" pos="0.001316 0 -0.062997" quat="0.642788 -0.766044 0 0" mesh="left_arm_shoulder_mount_visual" material="left_arm_shoulder_mount_visual_material"/>
        <geom type="mesh" class="collision" pos="0.001316 0 -0.062997" quat="0.642788 -0.766044 0 0" mesh="left_arm_shoulder_mount_collision" material="left_arm_shoulder_mount_collision_material"/>
        <!-- Link left_arm_top -->
        <body name="left_arm_top" pos="0.0242 0 -0.0675" quat="0 -0.707107 0 0.707107">
          <!-- Joint from left_arm_shoulder_mount to left_arm_top -->
          <joint axis="0 0 1" name="left_arm_ab" type="hinge" range="-1.570796 0.523599"/>
          <inertial pos="0 0.089956 0.025957" mass="0.5068" fullinertia="0.000598242 0.000396299 0.000549933 -1.7111e-06 1.04153e-06 2.34852e-05"/>
          <!-- Part left_arm_top_parts -->
          <geom type="mesh" class="visual" pos="0 0.089956 0.025957" quat="0.541675 0.454519 0.541675 -0.454519" mesh="left_arm_top_visual" material="left_arm_top_visual_material"/>
          <geom type="mesh" class="collision" pos="0 0.089956 0.025957" quat="0.541675 0.454519 0.541675 -0.454519" mesh="left_arm_top_collision" material="left_arm_top_collision_material"/>
          <!-- Link left_arm_elbow -->
          <body name="left_arm_elbow" pos="0 0.1212 0.02545" quat="0.5 0.5 -0.5 0.5">
            <!-- Joint from left_arm_top to left_arm_elbow -->
            <joint axis="0 0 1" name="left_arm_rot" type="hinge" range="-0.785398 0.785398"/>
            <inertial pos="0.002753 -0.001237 -0.109567" mass="0.5242" fullinertia="0.000744675 0.000878356 0.000289822 -7.74374e-07 -8.52343e-05 -8.77293e-06"/>
            <!-- Part left_arm_elbow_parts -->
            <geom type="mesh" class="visual" pos="0.002753 -0.001237 -0.109567" quat="0 0 -0.087156 0.996195" mesh="left_arm_elbow_visual" material="left_arm_elbow_visual_material"/>
            <geom type="mesh" class="collision" pos="0.002753 -0.001237 -0.109567" quat="0 0 -0.087156 0.996195" mesh="left_arm_elbow_collision" material="left_arm_elbow_collision_material"/>
            <!-- Link left_arm_lower_back -->
            <body name="left_arm_lower_back" pos="0 -0.02555 -0.121" quat="0.707107 -0.707107 0 0">
              <!-- Joint from left_arm_elbow to left_arm_lower_back -->
              <joint axis="0 0 1" name="left_arm_elbow" type="hinge" range="0 2.094395"/>
              <inertial pos="0.005553 0.084365 0.028884" mass="0.0923" fullinertia="0.00031165 4.32479e-05 0.000299733 -1.94132e-05 1.728e-06 2.62219e-05"/>
              <!-- Part left_arm_lower_back_parts -->
              <geom type="mesh" class="visual" pos="0.005553 0.084365 0.028884" quat="0 0 0.766044 -0.642788" mesh="left_arm_lower_back_visual" material="left_arm_lower_back_visual_material"/>
              <geom type="mesh" class="collision" pos="0.005553 0.084365 0.028884" quat="0 0 0.766044 -0.642788" mesh="left_arm_lower_back_collision" material="left_arm_lower_back_collision_material"/>
            </body>
          </body>
        </body>
      </body>
    </body>
  </worldbody>
  <asset>
    <mesh file="merged/body_collision.stl"/>
    <mesh file="merged/body_lower_collision.stl"/>
    <mesh file="merged/body_lower_visual.stl"/>
    <mesh file="merged/body_visual.stl"/>
    <mesh file="merged/head_collision.stl"/>
    <mesh file="merged/head_visual.stl"/>
    <mesh file="merged/hip_abd_mount_left_collision.stl"/>
    <mesh file="merged/hip_abd_mount_left_visual.stl"/>
    <mesh file="merged/hip_abd_mount_right_collision.stl"/>
    <mesh file="merged/hip_abd_mount_right_visual.stl"/>
    <mesh file="merged/knee_motor_mount_collision.stl"/>
    <mesh file="merged/knee_motor_mount_right_collision.stl"/>
    <mesh file="merged/knee_motor_mount_right_visual.stl"/>
    <mesh file="merged/knee_motor_mount_visual.stl"/>
    <mesh file="merged/left_arm_elbow_collision.stl"/>
    <mesh file="merged/left_arm_elbow_visual.stl"/>
    <mesh file="merged/left_arm_lower_back_collision.stl"/>
    <mesh file="merged/left_arm_lower_back_visual.stl"/>
    <mesh file="merged/left_arm_shoulder_mount_collision.stl"/>
    <mesh file="merged/left_arm_shoulder_mount_visual.stl"/>
    <mesh file="merged/left_arm_top_collision.stl"/>
    <mesh file="merged/left_arm_top_visual.stl"/>
    <mesh file="merged/left_foot_collision.stl"/>
    <mesh file="merged/left_foot_visual.stl"/>
    <mesh file="merged/leg_lower_left_collision.stl"/>
    <mesh file="merged/leg_lower_left_visual.stl"/>
    <mesh file="merged/leg_lower_right_collision.stl"/>
    <mesh file="merged/leg_lower_right_visual.stl"/>
    <mesh file="merged/leg_upper_upper_left_collision.stl"/>
    <mesh file="merged/leg_upper_upper_left_visual.stl"/>
    <mesh file="merged/leg_upper_upper_right_collision.stl"/>
    <mesh file="merged/leg_upper_upper_right_visual.stl"/>
    <mesh file="merged/lever_2_collision.stl"/>
    <mesh file="merged/lever_2_visual.stl"/>
    <mesh file="merged/lever_3_collision.stl"/>
    <mesh file="merged/lever_3_visual.stl"/>
    <mesh file="merged/lever_4_collision.stl"/>
    <mesh file="merged/lever_4_visual.stl"/>
    <mesh file="merged/lever_collision.stl"/>
    <mesh file="merged/lever_visual.stl"/>
    <mesh file="merged/linkage_long_collision.stl"/>
    <mesh file="merged/linkage_long_right_collision.stl"/>
    <mesh file="merged/linkage_long_right_visual.stl"/>
    <mesh file="merged/linkage_long_visual.stl"/>
    <mesh file="merged/linkage_short_collision.stl"/>
    <mesh file="merged/linkage_short_right_collision.stl"/>
    <mesh file="merged/linkage_short_right_visual.stl"/>
    <mesh file="merged/linkage_short_visual.stl"/>
    <mesh file="merged/neck_collision.stl"/>
    <mesh file="merged/neck_visual.stl"/>
    <mesh file="merged/right_arm_elbow_collision.stl"/>
    <mesh file="merged/right_arm_elbow_visual.stl"/>
    <mesh file="merged/right_arm_lower_back_collision.stl"/>
    <mesh file="merged/right_arm_lower_back_visual.stl"/>
    <mesh file="merged/right_arm_shoulder_mount_collision.stl"/>
    <mesh file="merged/right_arm_shoulder_mount_visual.stl"/>
    <mesh file="merged/right_arm_top_collision.stl"/>
    <mesh file="merged/right_arm_top_visual.stl"/>
    <mesh file="merged/right_foot_collision.stl"/>
    <mesh file="merged/right_foot_visual.stl"/>
    <mesh file="merged/u_join_box_left_collision.stl"/>
    <mesh file="merged/u_join_box_left_visual.stl"/>
    <mesh file="merged/u_join_box_right_collision.stl"/>
    <mesh file="merged/u_join_box_right_visual.stl"/>
    <material name="body_visual_material" rgba="0.456436 0.589096 0.720618 1"/>
    <material name="body_collision_material" rgba="0.456436 0.589096 0.720618 1"/>
    <material name="body_lower_visual_material" rgba="0.581819 0.746212 0.860752 1"/>
    <material name="body_lower_collision_material" rgba="0.581819 0.746212 0.860752 1"/>
    <material name="hip_abd_mount_left_visual_material" rgba="0.528347 0.656694 0.799302 1"/>
    <material name="hip_abd_mount_left_collision_material" rgba="0.528347 0.656694 0.799302 1"/>
    <material name="leg_upper_upper_left_visual_material" rgba="0.542678 0.65846 0.787107 1"/>
    <material name="leg_upper_upper_left_collision_material" rgba="0.542678 0.65846 0.787107 1"/>
    <material name="knee_motor_mount_visual_material" rgba="0.536204 0.661106 0.799887 1"/>
    <material name="knee_motor_mount_collision_material" rgba="0.536204 0.661106 0.799887 1"/>
    <material name="leg_lower_left_visual_material" rgba="0.581114 0.685788 0.748593 1"/>
    <material name="leg_lower_left_collision_material" rgba="0.581114 0.685788 0.748593 1"/>
    <material name="u_join_box_left_visual_material" rgba="0.917647 0.917647 0.917647 1"/>
    <material name="u_join_box_left_collision_material" rgba="0.917647 0.917647 0.917647 1"/>
    <material name="left_foot_visual_material" rgba="0.486257 0.486257 0.486257 1"/>
    <material name="left_foot_collision_material" rgba="0.486257 0.486257 0.486257 1"/>
    <material name="lever_visual_material" rgba="0.647059 0.647059 0.647059 1"/>
    <material name="lever_collision_material" rgba="0.647059 0.647059 0.647059 1"/>
    <material name="linkage_long_visual_material" rgba="0.917647 0.917647 0.917647 1"/>
    <material name="linkage_long_collision_material" rgba="0.917647 0.917647 0.917647 1"/>
    <material name="lever_2_visual_material" rgba="0.647059 0.647059 0.647059 1"/>
    <material name="lever_2_collision_material" rgba="0.647059 0.647059 0.647059 1"/>
    <material name="linkage_short_visual_material" rgba="0.8 0.8 0.8 1"/>
    <material name="linkage_short_collision_material" rgba="0.8 0.8 0.8 1"/>
    <material name="hip_abd_mount_right_visual_material" rgba="0.528347 0.656694 0.799302 1"/>
    <material name="hip_abd_mount_right_collision_material" rgba="0.528347 0.656694 0.799302 1"/>
    <material name="leg_upper_upper_right_visual_material" rgba="0.544106 0.639692 0.7459 1"/>
    <material name="leg_upper_upper_right_collision_material" rgba="0.544106 0.639692 0.7459 1"/>
    <material name="knee_motor_mount_right_visual_material" rgba="0.536204 0.661106 0.799887 1"/>
    <material name="knee_motor_mount_right_collision_material" rgba="0.536204 0.661106 0.799887 1"/>
    <material name="leg_lower_right_visual_material" rgba="0.580813 0.68535 0.748072 1"/>
    <material name="leg_lower_right_collision_material" rgba="0.580813 0.68535 0.748072 1"/>
    <material name="u_join_box_right_visual_material" rgba="0.917647 0.917647 0.917647 1"/>
    <material name="u_join_box_right_collision_material" rgba="0.917647 0.917647 0.917647 1"/>
    <material name="right_foot_visual_material" rgba="0.486257 0.486257 0.486257 1"/>
    <material name="right_foot_collision_material" rgba="0.486257 0.486257 0.486257 1"/>
    <material name="lever_3_visual_material" rgba="0.647059 0.647059 0.647059 1"/>
    <material name="lever_3_collision_material" rgba="0.647059 0.647059 0.647059 1"/>
    <material name="linkage_long_right_visual_material" rgba="0.917647 0.917647 0.917647 1"/>
    <material name="linkage_long_right_collision_material" rgba="0.917647 0.917647 0.917647 1"/>
    <material name="lever_4_visual_material" rgba="0.647059 0.647059 0.647059 1"/>
    <material name="lever_4_collision_material" rgba="0.647059 0.647059 0.647059 1"/>
    <material name="linkage_short_right_visual_material" rgba="0.8 0.8 0.8 1"/>
    <material name="linkage_short_right_collision_material" rgba="0.8 0.8 0.8 1"/>
    <material name="neck_visual_material" rgba="0.789855 0.833863 0.882102 1"/>
    <material name="neck_collision_material" rgba="0.789855 0.833863 0.882102 1"/>
    <material name="head_visual_material" rgba="0.32549 0.529412 0.752941 1"/>
    <material name="head_collision_material" rgba="0.32549 0.529412 0.752941 1"/>
    <material name="right_arm_shoulder_mount_visual_material" rgba="0.606068 0.778849 0.882518 1"/>
    <material name="right_arm_shoulder_mount_collision_material" rgba="0.606068 0.778849 0.882518 1"/>
    <material name="right_arm_top_visual_material" rgba="0.633006 0.794612 0.891576 1"/>
    <material name="right_arm_top_collision_material" rgba="0.633006 0.794612 0.891576 1"/>
    <material name="right_arm_elbow_visual_material" rgba="0.62276 0.774626 0.865745 1"/>
    <material name="right_arm_elbow_collision_material" rgba="0.62276 0.774626 0.865745 1"/>
    <material name="right_arm_lower_back_visual_material" rgba="0.749241 0.87683 0.949959 1"/>
    <material name="right_arm_lower_back_collision_material" rgba="0.749241 0.87683 0.949959 1"/>
    <material name="left_arm_shoulder_mount_visual_material" rgba="0.606068 0.778849 0.882518 1"/>
    <material name="left_arm_shoulder_mount_collision_material" rgba="0.606068 0.778849 0.882518 1"/>
    <material name="left_arm_top_visual_material" rgba="0.633006 0.794612 0.891576 1"/>
    <material name="left_arm_top_collision_material" rgba="0.633006 0.794612 0.891576 1"/>
    <material name="left_arm_elbow_visual_material" rgba="0.62276 0.774626 0.865745 1"/>
    <material name="left_arm_elbow_collision_material" rgba="0.62276 0.774626 0.865745 1"/>
    <material name="left_arm_lower_back_visual_material" rgba="0.749241 0.87683 0.949959 1"/>
    <material name="left_arm_lower_back_collision_material" rgba="0.749241 0.87683 0.949959 1"/>
  </asset>
  <actuator>
    <position class="humanoid" name="body_yaw" joint="body_yaw" kp="100" inheritrange="1"/>
    <position class="humanoid" name="left_hip_flex" joint="left_hip_flex" kp="100" inheritrange="1"/>
    <position class="humanoid" name="left_hip_ab" joint="left_hip_ab" kp="100" inheritrange="1"/>
    <position class="humanoid" name="left_hip_rot" joint="left_hip_rot" kp="100" inheritrange="1"/>
    <position class="humanoid" name="left_knee" joint="left_knee" kp="100" inheritrange="1"/>
    <position class="humanoid" name="left_foot_pitch" joint="left_foot_pitch" kp="100" inheritrange="1"/>
    <position class="humanoid" name="left_foot_roll" joint="left_foot_roll" kp="100" inheritrange="1"/>
    <position class="humanoid" name="right_hip_flex" joint="right_hip_flex" kp="100" inheritrange="1"/>
    <position class="humanoid" name="right_hip_ab" joint="right_hip_ab" kp="100" inheritrange="1"/>
    <position class="humanoid" name="right_hip_rot" joint="right_hip_rot" kp="100" inheritrange="1"/>
    <position class="humanoid" name="right_knee" joint="right_knee" kp="100" inheritrange="1"/>
    <position class="humanoid" name="right_foot_pitch" joint="right_foot_pitch" kp="100" inheritrange="1"/>
    <position class="humanoid" name="right_foot_roll" joint="right_foot_roll" kp="100" inheritrange="1"/>
    <position class="humanoid" name="head_yaw" joint="head_yaw" kp="100" inheritrange="1"/>
    <position class="humanoid" name="head_pitch" joint="head_pitch" kp="100" inheritrange="1"/>
    <position class="humanoid" name="right_arm_flex" joint="right_arm_flex" kp="100" inheritrange="1"/>
    <position class="humanoid" name="right_arm_ab" joint="right_arm_ab" kp="100" inheritrange="1"/>
    <position class="humanoid" name="right_arm_rot" joint="right_arm_rot" kp="100" inheritrange="1"/>
    <position class="humanoid" name="right_arm_elbow" joint="right_arm_elbow" kp="100" inheritrange="1"/>
    <position class="humanoid" name="left_arm_flex" joint="left_arm_flex" kp="100" inheritrange="1"/>
    <position class="humanoid" name="left_arm_ab" joint="left_arm_ab" kp="100" inheritrange="1"/>
    <position class="humanoid" name="left_arm_rot" joint="left_arm_rot" kp="100" inheritrange="1"/>
    <position class="humanoid" name="left_arm_elbow" joint="left_arm_elbow" kp="100" inheritrange="1"/>
  </actuator>
  <equality>
    <connect site1="closing_left_ankle_left_linkage_1" site2="closing_left_ankle_left_linkage_2"/>
    <connect site1="closing_left_ankle_right_linkage_1" site2="closing_left_ankle_right_linkage_2"/>
    <connect site1="closing_right_ankle_right_linkage_1" site2="closing_right_ankle_right_linkage_2"/>
    <connect site1="closing_right_ankle_left_linkage_1" site2="closing_right_ankle_left_linkage_2"/>
  </equality>
</mujoco>
